from pathlib import Path
from types import GeneratorType
import logging

import pytest

from promptflow._sdk._pf_client import PFClient
from promptflow._sdk._constants import LOGGER_NAME
from promptflow.exceptions import UserErrorException

PROMOTFLOW_ROOT = Path(__file__) / "../../../.."

TEST_ROOT = Path(__file__).parent.parent.parent
MODEL_ROOT = TEST_ROOT / "test_configs/e2e_samples"
CONNECTION_FILE = (PROMOTFLOW_ROOT / "connections.json").resolve().absolute().as_posix()
FLOWS_DIR = (TEST_ROOT / "test_configs/flows").resolve().absolute().as_posix()
FLOW_RESULT_KEYS = ["category", "evidence"]

_client = PFClient()


@pytest.mark.usefixtures("use_secrets_config_file", "setup_local_connection")
@pytest.mark.sdk_test
@pytest.mark.e2etest
class TestFlowTest:
    def test_pf_test_flow(self):
        inputs = {"url": "https://www.youtube.com/watch?v=o5ZQyXaAv1g", "answer": "Channel", "evidence": "Url"}
        flow_path = Path(f"{FLOWS_DIR}/web_classification").absolute()

        result = _client.test(flow=flow_path, inputs=inputs)
        assert all([key in FLOW_RESULT_KEYS for key in result])

        result = _client.test(flow=f"{FLOWS_DIR}/web_classification")
        assert all([key in FLOW_RESULT_KEYS for key in result])

    def test_pf_test_with_streaming_output(self):
        flow_path = Path(f"{FLOWS_DIR}/chat_flow_with_stream_output")
        result = _client.test(flow=flow_path)
        chat_output = result["answer"]
        assert isinstance(chat_output, GeneratorType)
        assert "".join(chat_output)

    def test_pf_test_node(self):
        inputs = {"classify_with_llm.output": '{"category": "App", "evidence": "URL"}'}
        flow_path = Path(f"{FLOWS_DIR}/web_classification").absolute()

        result = _client.test(flow=flow_path, inputs=inputs, node="convert_to_dict")
        assert all([key in FLOW_RESULT_KEYS for key in result])

    def test_pf_test_flow_with_variant(self):
        inputs = {"url": "https://www.youtube.com/watch?v=o5ZQyXaAv1g", "answer": "Channel", "evidence": "Url"}

        result = _client.test(
            flow=f"{FLOWS_DIR}/web_classification", inputs=inputs, variant="${summarize_text_content.variant_1}"
        )
        assert all([key in FLOW_RESULT_KEYS for key in result])

    def test_pf_test_with_additional_includes(self, caplog):
        with caplog.at_level(level=logging.WARNING, logger=LOGGER_NAME):
            inputs = {"url": "https://www.youtube.com/watch?v=o5ZQyXaAv1g", "answer": "Channel", "evidence": "Url"}
            result = _client.test(flow=f"{FLOWS_DIR}/web_classification_with_additional_include", inputs=inputs)
        duplicate_file_content = "Found duplicate file in additional includes"
        assert any([duplicate_file_content in record.message for record in caplog.records])
        assert all([key in FLOW_RESULT_KEYS for key in result])

        inputs = {"classify_with_llm.output": '{"category": "App", "evidence": "URL"}'}
        result = _client.test(flow=f"{FLOWS_DIR}/web_classification", inputs=inputs, node="convert_to_dict")
        assert all([key in FLOW_RESULT_KEYS for key in result])

        # Test additional includes don't exist
        with pytest.raises(ValueError) as e:
            _client.test(flow=f"{FLOWS_DIR}/web_classification_with_invalid_additional_include")
        assert "Unable to find additional include ../invalid/file/path" in str(e.value)

    def test_pf_flow_test_with_symbolic(self, prepare_symbolic_flow):
        inputs = {"url": "https://www.youtube.com/watch?v=o5ZQyXaAv1g", "answer": "Channel", "evidence": "Url"}
        result = _client.test(flow=f"{FLOWS_DIR}/web_classification_with_additional_include", inputs=inputs)
        assert all([key in FLOW_RESULT_KEYS for key in result])

        inputs = {"classify_with_llm.output": '{"category": "App", "evidence": "URL"}'}
        result = _client.test(flow=f"{FLOWS_DIR}/web_classification", inputs=inputs, node="convert_to_dict")
        assert all([key in FLOW_RESULT_KEYS for key in result])

    def test_pf_flow_test_with_exception(self, capsys):
        # Test flow with exception
        inputs = {"url": "https://www.youtube.com/watch?v=o5ZQyXaAv1g", "answer": "Channel", "evidence": "Url"}
        flow_path = Path(f"{FLOWS_DIR}/web_classification_with_exception").absolute()

        with pytest.raises(UserErrorException) as exception:
            _client.test(flow=flow_path, inputs=inputs)
        assert "Execution failure in 'convert_to_dict': (Exception) mock exception" in str(exception.value)

        # Test node with exception
        inputs = {"classify_with_llm.output": '{"category": "App", "evidence": "URL"}'}
        with pytest.raises(Exception) as exception:
            _client.test(flow=flow_path, inputs=inputs, node="convert_to_dict")
        output = capsys.readouterr()
        assert "convert_to_dict.py" in output.out
        assert "mock exception" in str(exception.value)

    def test_node_test_with_connection_input(self):
        flow_path = Path(f"{FLOWS_DIR}/basic-with-connection").absolute()
        inputs = {
            "connection": "azure_open_ai_connection",
            "hello_prompt.output": "Write a simple Hello World! "
            "program that displays the greeting message when executed.",
        }
        result = _client.test(
            flow=flow_path,
            inputs=inputs,
            node="echo_my_prompt",
            environment_variables={"API_TYPE": "${azure_open_ai_connection.api_type}"},
        )
        assert result

    def test_pf_flow_with_aggregation(self):
        flow_path = Path(f"{FLOWS_DIR}/classification_accuracy_evaluation").absolute()
        inputs = {"variant_id": "variant_0", "groundtruth": "Pdf", "prediction": "PDF"}
        result = _client._flows._test(flow=flow_path, inputs=inputs)
        assert "calculate_accuracy" in result.node_run_infos
        assert result.run_info.metrics == {"accuracy": 1.0}
